Workbook

Sheet Сводка
A1: Замеры устойчивости: 15 пресс-релизов Сбера, по 5 прогонов
A2: Модель Qwen 3.8 27B (4 бита, локально), спецификация v7, температура 0; в каждом прогоне свой порядок показателей в запросе. Оценки прогонов — на листах отчётов (ссылка в колонке A); все числа этого листа, кроме колонок K и L, — формулы по этим листам.
A3: Колонка K перечисляет показатели, оценки которых разошлись; L — контрольный прогон того же метода при температуре 0,7 (данные, не формула).
A5: Сбер
A6: Отчёт | B6: Период | C6: Совпали во всех 5 (из 24) | D6: Доля | E6: Вывод одинаков во всех 5 | F6: Итоговая сумма | G6: Вывод | H6: Сумма: минимум | I6: Сумма: максимум | J6: Разброс суммы | K6: Разошлись: показатель (5 прогонов) | L6: Контроль при T=0,7: совпали (из 24)
A7: 2022_q4 | B7: 4 кв. и 12 мес. 2022 | C7: ='2022_q4'!C33 -> 24 | D7: =C7/24 -> 1 | E7: ='2022_q4'!C34 -> да | F7: ='2022_q4'!H30 -> -2 | G7: ='2022_q4'!H31 -> mixed | H7: ='2022_q4'!C35 -> -2 | I7: ='2022_q4'!C36 -> -2 | J7: =I7-H7 -> 0 | K7: — | L7: 22
A8: 2023_q1 | B8: 1 кв. 2023 | C8: ='2023_q1'!C33 -> 21 | D8: =C8/24 -> 0.875 | E8: ='2023_q1'!C34 -> да | F8: ='2023_q1'!H30 -> 12 | G8: ='2023_q1'!H31 -> mixed | H8: ='2023_q1'!C35 -> 11 | I8: ='2023_q1'!C36 -> 12 | J8: =I8-H8 -> 1 | K8: Чистые процентные доходы (+1 +1 +1 0 +1); Чистые комиссионные доходы (−1 −1 −1 0 −1); Чистая процентная маржа (NIM) (+1 +1 +1 0 +1) | L8: 22
A9: 2023_q2 | B9: 2 кв. 2023 (6 мес.) | C9: ='2023_q2'!C33 -> 17 | D9: =C9/24 -> 0.70833333 | E9: ='2023_q2'!C34 -> нет | F9: ='2023_q2'!H30 -> 12 | G9: ='2023_q2'!H31 -> mixed | H9: ='2023_q2'!C35 -> 9 | I9: ='2023_q2'!C36 -> 16 | J9: =I9-H9 -> 7 | K9: Чистая прибыль (+1 0 +1 +1 0); Рентабельность капитала (ROE) (+1 0 0 +1 0); Чистые процентные доходы (+1 0 +1 +1 0); Чистые комиссионные доходы (+1 0 0 0 0); Чистая процентная маржа (NIM) (+1 0 0 0 0); Отношение расходов к доходам (CIR) (+1 0 +1 +1 −1); Тональность руководителя (+2 +1 +1 +1 +2) | L9: 18
A10: 2023_q3 | B10: 3 кв. 2023 (9 мес.) | C10: ='2023_q3'!C33 -> 23 | D10: =C10/24 -> 0.95833333 | E10: ='2023_q3'!C34 -> да | F10: ='2023_q3'!H30 -> 12 | G10: ='2023_q3'!H31 -> mixed | H10: ='2023_q3'!C35 -> 11 | I10: ='2023_q3'!C36 -> 12 | J10: =I10-H10 -> 1 | K10: Отношение расходов к доходам (CIR) (+1 0 +1 +1 +1) | L10: 16
A11: 2023_q4 | B11: 4 кв. и 12 мес. 2023 | C11: ='2023_q4'!C33 -> 22 | D11: =C11/24 -> 0.91666667 | E11: ='2023_q4'!C34 -> да | F11: ='2023_q4'!H30 -> 29 | G11: ='2023_q4'!H31 -> strong | H11: ='2023_q4'!C35 -> 29 | I11: ='2023_q4'!C36 -> 31 | J11: =I11-H11 -> 2 | K11: Достаточность капитала (Н20.0) (−1 0 −1 −1 −1); Внешние условия (0 0 −1 −1 −1) | L11: 23
A12: 2024_q1 | B12: 1 кв. 2024 | C12: ='2024_q1'!C33 -> 23 | D12: =C12/24 -> 0.95833333 | E12: ='2024_q1'!C34 -> да | F12: ='2024_q1'!H30 -> 9 | G12: ='2024_q1'!H31 -> mixed | H12: ='2024_q1'!C35 -> 8 | I12: ='2024_q1'!C36 -> 9 | J12: =I12-H12 -> 1 | K12: Качество портфеля (0 +1 0 +1 +1) | L12: 22
A13: 2024_q2 | B13: 2 кв. 2024 (6 мес.) | C13: ='2024_q2'!C33 -> 22 | D13: =C13/24 -> 0.91666667 | E13: ='2024_q2'!C34 -> да | F13: ='2024_q2'!H30 -> 14 | G13: ='2024_q2'!H31 -> strong | H13: ='2024_q2'!C35 -> 13 | I13: ='2024_q2'!C36 -> 15 | J13: =I13-H13 -> 2 | K13: Качество портфеля (+1 +1 0 +1 +1); Внешние условия (+1 −1 0 0 0) | L13: 21
A14: 2024_q3 | B14: 3 кв. 2024 (9 мес.) | C14: ='2024_q3'!C33 -> 21 | D14: =C14/24 -> 0.875 | E14: ='2024_q3'!C34 -> да | F14: ='2024_q3'!H30 -> 4 | G14: ='2024_q3'!H31 -> mixed | H14: ='2024_q3'!C35 -> 2 | I14: ='2024_q3'!C36 -> 5 | J14: =I14-H14 -> 3 | K14: Стоимость риска (CoR) (−2 −2 0 −2 −2); Дивиденды (+1 +1 +1 +1 0); Тональность руководителя (+1 −1 0 +1 +1) | L14: 22
A15: 2024_q4 | B15: 4 кв. и 12 мес. 2024 | C15: ='2024_q4'!C33 -> 21 | D15: =C15/24 -> 0.875 | E15: ='2024_q4'!C34 -> да | F15: ='2024_q4'!H30 -> 3 | G15: ='2024_q4'!H31 -> mixed | H15: ='2024_q4'!C35 -> 3 | I15: ='2024_q4'!C36 -> 4 | J15: =I15-H15 -> 1 | K15: Расходы на резервы (−1 −2 −2 −1 −2); Качество портфеля (−1 0 0 −1 −1); Доля рынка (+1 +1 +1 0 +1) | L15: 19
A16: 2025_q1 | B16: 1 кв. 2025 | C16: ='2025_q1'!C33 -> 24 | D16: =C16/24 -> 1 | E16: ='2025_q1'!C34 -> да | F16: ='2025_q1'!H30 -> 6 | G16: ='2025_q1'!H31 -> mixed | H16: ='2025_q1'!C35 -> 6 | I16: ='2025_q1'!C36 -> 6 | J16: =I16-H16 -> 0 | K16: — | L16: 22
A17: 2025_q2 | B17: 2 кв. 2025 (6 мес.) | C17: ='2025_q2'!C33 -> 23 | D17: =C17/24 -> 0.95833333 | E17: ='2025_q2'!C34 -> да | F17: ='2025_q2'!H30 -> 5 | G17: ='2025_q2'!H31 -> mixed | H17: ='2025_q2'!C35 -> 4 | I17: ='2025_q2'!C36 -> 5 | J17: =I17-H17 -> 1 | K17: Корпоративный портфель (0 +1 +1 +1 +1) | L17: 21
A18: 2025_q3 | B18: 3 кв. 2025 (9 мес.) | C18: ='2025_q3'!C33 -> 24 | D18: =C18/24 -> 1 | E18: ='2025_q3'!C34 -> да | F18: ='2025_q3'!H30 -> 4 | G18: ='2025_q3'!H31 -> mixed | H18: ='2025_q3'!C35 -> 4 | I18: ='2025_q3'!C36 -> 4 | J18: =I18-H18 -> 0 | K18: — | L18: 23
A19: 2025_q4 | B19: 4 кв. и 12 мес. 2025 | C19: ='2025_q4'!C33 -> 21 | D19: =C19/24 -> 0.875 | E19: ='2025_q4'!C34 -> нет | F19: ='2025_q4'!H30 -> 13 | G19: ='2025_q4'!H31 -> strong | H19: ='2025_q4'!C35 -> 11 | I19: ='2025_q4'!C36 -> 13 | J19: =I19-H19 -> 2 | K19: Корпоративный портфель (+2 +1 +1 +2 +2); Средства клиентов (+1 +2 +2 +2 +2); Тональность руководителя (+2 +1 0 +1 −1) | L19: 19
A20: 2026_q1 | B20: 1 кв. 2026 | C20: ='2026_q1'!C33 -> 22 | D20: =C20/24 -> 0.91666667 | E20: ='2026_q1'!C34 -> да | F20: ='2026_q1'!H30 -> 9 | G20: ='2026_q1'!H31 -> mixed | H20: ='2026_q1'!C35 -> 7 | I20: ='2026_q1'!C36 -> 9 | J20: =I20-H20 -> 2 | K20: Качество портфеля (0 +1 +1 +1 +1); Технологическое развитие (0 +1 +1 +1 0) | L20: 21
A21: 2026_q2 | B21: 2 кв. 2026 (6 мес.) | C21: ='2026_q2'!C33 -> 23 | D21: =C21/24 -> 0.95833333 | E21: ='2026_q2'!C34 -> да | F21: ='2026_q2'!H30 -> 20 | G21: ='2026_q2'!H31 -> strong | H21: ='2026_q2'!C35 -> 20 | I21: ='2026_q2'!C36 -> 21 | J21: =I21-H21 -> 1 | K21: Цифровые метрики (+1 0 0 +1 0) | L21: 18
B22: Итого по 15 отчётам | C22: =SUM(C7:C21) -> 331 | D22: =C22/(15*24) -> 0.91944444 | E22: =COUNTIF(E7:E21,"да") -> 13 | F22: из 15 отчётов — вывод одинаков | L22: =SUM(L7:L21) -> 309
A24: Другие банки: проверка переноса, в основную сдачу не входят
A25: Отчёт | B25: Период | C25: Совпали во всех 5 (из 24) | D25: Доля | E25: Вывод одинаков во всех 5 | F25: Итоговая сумма | G25: Вывод | H25: Сумма: минимум | I25: Сумма: максимум | J25: Разброс суммы | K25: Разошлись: показатель (5 прогонов) | L25: Контроль при T=0,7: совпали (из 24)
A26: vtb_2026_q1 | B26: ВТБ, 1 кв. 2026 | C26: ='vtb_2026_q1'!C33 -> 21 | D26: =C26/24 -> 0.875 | E26: ='vtb_2026_q1'!C34 -> да | F26: ='vtb_2026_q1'!H30 -> 2 | G26: ='vtb_2026_q1'!H31 -> mixed | H26: ='vtb_2026_q1'!C35 -> 0 | I26: ='vtb_2026_q1'!C36 -> 3 | J26: =I26-H26 -> 3 | K26: Качество портфеля (+1 +1 +1 −1 0); Внешние условия (0 −1 −1 −1 −1); Тональность руководителя (+1 +1 +2 +1 +1) | L26: 21
A27: tbank_2024_q4 | B27: Т-Технологии, 4 кв. 2024 | C27: ='tbank_2024_q4'!C33 -> 22 | D27: =C27/24 -> 0.91666667 | E27: ='tbank_2024_q4'!C34 -> нет | F27: ='tbank_2024_q4'!H30 -> 12 | G27: ='tbank_2024_q4'!H31 -> mixed | H27: ='tbank_2024_q4'!C35 -> 11 | I27: ='tbank_2024_q4'!C36 -> 14 | J27: =I27-H27 -> 3 | K27: Операционные расходы (0 +2 0 +2 0); Внешние условия (0 −1 −1 0 0) | L27: 19
A28: tbank_2026_q1 | B28: Т-Технологии, 1 кв. 2026 | C28: ='tbank_2026_q1'!C33 -> 20 | D28: =C28/24 -> 0.83333333 | E28: ='tbank_2026_q1'!C34 -> да | F28: ='tbank_2026_q1'!H30 -> 15 | G28: ='tbank_2026_q1'!H31 -> strong | H28: ='tbank_2026_q1'!C35 -> 15 | I28: ='tbank_2026_q1'!C36 -> 19 | J28: =I28-H28 -> 4 | K28: Прибыль на акцию (EPS) (+2 0 0 +2 0); Операционные расходы (+1 0 0 0 0); Стоимость риска (CoR) (0 −1 −1 −1 0); Дивиденды (+1 +1 +1 +1 +2) | L28: 18
A29: tbank_2026_q2 | B29: Т-Технологии, 2 кв. 2026 | C29: ='tbank_2026_q2'!C33 -> 19 | D29: =C29/24 -> 0.79166667 | E29: ='tbank_2026_q2'!C34 -> да | F29: ='tbank_2026_q2'!H30 -> 6 | G29: ='tbank_2026_q2'!H31 -> mixed | H29: ='tbank_2026_q2'!C35 -> 6 | I29: ='tbank_2026_q2'!C36 -> 10 | J29: =I29-H29 -> 4 | K29: Прибыль на акцию (EPS) (0 0 +1 +1 0); Рентабельность капитала (ROE) (−1 −1 −1 +1 −1); Операционные расходы (+1 0 +1 0 0); Отношение расходов к доходам (CIR) (−1 −1 −1 0 −1); Внешние условия (0 0 +1 0 0) | L29: 18
B30: Итого по 4 отчётам | C30: =SUM(C26:C29) -> 82 | D30: =C30/(4*24) -> 0.85416667 | E30: =COUNTIF(E26:E29,"да") -> 3 | F30: из 4 отчётов — вывод одинаков | L30: =SUM(L26:L29) -> 76

Sheet 2022_q4
A1: 4 кв. и 12 мес. 2022: оценки пяти прогонов
A2: Исходный файл: 2022_ifrs_.pdf
A3: Прогоны отличаются только порядком показателей в запросе. Итог — медиана пяти оценок (совпадает с самым частым значением). «нет» в колонке I — хрупкая клетка, её нужно проверить человеку.
A5: Блок | B5: Показатель | C5: Прогон 1 | D5: Прогон 2 | E5: Прогон 3 | F5: Прогон 4 | G5: Прогон 5 | H5: Итог (медиана) | I5: Совпали во всех 5 | J5: Кто ставит
A6: Прибыльность | B6: Чистая прибыль | C6: -2 | D6: -2 | E6: -2 | F6: -2 | G6: -2 | H6: =MEDIAN(C6:G6) -> -2 | I6: =IF(MAX(C6:G6)=MIN(C6:G6),"да","нет") -> да | J6: код
A7: Прибыльность | B7: Прибыль на акцию (EPS) | C7: -2 | D7: -2 | E7: -2 | F7: -2 | G7: -2 | H7: =MEDIAN(C7:G7) -> -2 | I7: =IF(MAX(C7:G7)=MIN(C7:G7),"да","нет") -> да | J7: код
A8: Прибыльность | B8: Рентабельность капитала (ROE) | C8: -2 | D8: -2 | E8: -2 | F8: -2 | G8: -2 | H8: =MEDIAN(C8:G8) -> -2 | I8: =IF(MAX(C8:G8)=MIN(C8:G8),"да","нет") -> да | J8: код
A9: Прибыльность | B9: Прогноз менеджмента | C9: 0 | D9: 0 | E9: 0 | F9: 0 | G9: 0 | H9: =MEDIAN(C9:G9) -> 0 | I9: =IF(MAX(C9:G9)=MIN(C9:G9),"да","нет") -> да | J9: модель
A10: Доходы | B10: Чистые процентные доходы | C10: 1 | D10: 1 | E10: 1 | F10: 1 | G10: 1 | H10: =MEDIAN(C10:G10) -> 1 | I10: =IF(MAX(C10:G10)=MIN(C10:G10),"да","нет") -> да | J10: код
A11: Доходы | B11: Чистые комиссионные доходы | C11: 2 | D11: 2 | E11: 2 | F11: 2 | G11: 2 | H11: =MEDIAN(C11:G11) -> 2 | I11: =IF(MAX(C11:G11)=MIN(C11:G11),"да","нет") -> да | J11: код
A12: Доходы | B12: Чистая процентная маржа (NIM) | C12: 0 | D12: 0 | E12: 0 | F12: 0 | G12: 0 | H12: =MEDIAN(C12:G12) -> 0 | I12: =IF(MAX(C12:G12)=MIN(C12:G12),"да","нет") -> да | J12: код
A13: Эффективность | B13: Операционные расходы | C13: 0 | D13: 0 | E13: 0 | F13: 0 | G13: 0 | H13: =MEDIAN(C13:G13) -> 0 | I13: =IF(MAX(C13:G13)=MIN(C13:G13),"да","нет") -> да | J13: код
A14: Эффективность | B14: Отношение расходов к доходам (CIR) | C14: -2 | D14: -2 | E14: -2 | F14: -2 | G14: -2 | H14: =MEDIAN(C14:G14) -> -2 | I14: =IF(MAX(C14:G14)=MIN(C14:G14),"да","нет") -> да | J14: код
A15: Риск | B15: Стоимость риска (CoR) | C15: -2 | D15: -2 | E15: -2 | F15: -2 | G15: -2 | H15: =MEDIAN(C15:G15) -> -2 | I15: =IF(MAX(C15:G15)=MIN(C15:G15),"да","нет") -> да | J15: код
A16: Риск | B16: Расходы на резервы | C16: -2 | D16: -2 | E16: -2 | F16: -2 | G16: -2 | H16: =MEDIAN(C16:G16) -> -2 | I16: =IF(MAX(C16:G16)=MIN(C16:G16),"да","нет") -> да | J16: код
A17: Риск | B17: Качество портфеля | C17: 1 | D17: 1 | E17: 1 | F17: 1 | G17: 1 | H17: =MEDIAN(C17:G17) -> 1 | I17: =IF(MAX(C17:G17)=MIN(C17:G17),"да","нет") -> да | J17: модель
... A29: Среда | B29: Тональность руководителя | C29: -2 | D29: -2 | E29: -2 | F29: -2 | G29: -2 | H29: =MEDIAN(C29:G29) -> -2 | I29: =IF(MAX(C29:G29)=MIN(C29:G29),"да","нет") -> да | J29: модель
B30: Сумма 24 оценок | C30: =SUM(C6:C29) -> -2 | D30: =SUM(D6:D29) -> -2 | E30: =SUM(E6:E29) -> -2 | F30: =SUM(F6:F29) -> -2 | G30: =SUM(G6:G29) -> -2 | H30: =SUM(H6:H29) -> -2
B31: Вывод (сумма > 12 — strong, < −12 — weak) | C31: =IF(C30>12,"strong",IF(C30<-12,"weak","mixed")) -> mixed | D31: =IF(D30>12,"strong",IF(D30<-12,"weak","mixed")) -> mixed | E31: =IF(E30>12,"strong",IF(E30<-12,"weak","mixed")) -> mixed | F31: =IF(F30>12,"strong",IF(F30<-12,"weak","mixed")) -> mixed | G31: =IF(G30>12,"strong",IF(G30<-12,"weak","mixed")) -> mixed | H31: =IF(H30>12,"strong",IF(H30<-12,"weak","mixed")) -> mixed
B33: Совпали во всех 5 прогонах (из 24) | C33: =COUNTIF(I6:I29,"да") -> 24
B34: Вывод одинаков во всех 5 прогонах | C34: =IF(COUNTIF(C31:G31,C31)=5,"да","нет") -> да
B35: Сумма по прогонам: минимум | C35: =MIN(C30:G30) -> -2
B36: Сумма по прогонам: максимум | C36: =MAX(C30:G30) -> -2

Sheet 2023_q1
A1: 1 кв. 2023: оценки пяти прогонов
A2: Исходный файл: 2023_q1_ifrs_.pdf
A3: Прогоны отличаются только порядком показателей в запросе. Итог — медиана пяти оценок (совпадает с самым частым значением). «нет» в колонке I — хрупкая клетка, её нужно проверить человеку.
A5: Блок | B5: Показатель | C5: Прогон 1 | D5: Прогон 2 | E5: Прогон 3 | F5: Прогон 4 | G5: Прогон 5 | H5: Итог (медиана) | I5: Совпали во всех 5 | J5: Кто ставит
A6: Прибыльность | B6: Чистая прибыль | C6: 0 | D6: 0 | E6: 0 | F6: 0 | G6: 0 | H6: =MEDIAN(C6:G6) -> 0 | I6: =IF(MAX(C6:G6)=MIN(C6:G6),"да","нет") -> да | J6: код
A7: Прибыльность | B7: Прибыль на акцию (EPS) | C7: 0 | D7: 0 | E7: 0 | F7: 0 | G7: 0 | H7: =MEDIAN(C7:G7) -> 0 | I7: =IF(MAX(C7:G7)=MIN(C7:G7),"да","нет") -> да | J7: код
A8: Прибыльность | B8: Рентабельность капитала (ROE) | C8: 0 | D8: 0 | E8: 0 | F8: 0 | G8: 0 | H8: =MEDIAN(C8:G8) -> 0 | I8: =IF(MAX(C8:G8)=MIN(C8:G8),"да","нет") -> да | J8: код
A9: Прибыльность | B9: Прогноз менеджмента | C9: 1 | D9: 1 | E9: 1 | F9: 1 | G9: 1 | H9: =MEDIAN(C9:G9) -> 1 | I9: =IF(MAX(C9:G9)=MIN(C9:G9),"да","нет") -> да | J9: модель
A10: Доходы | B10: Чистые процентные доходы | C10: 1 | D10: 1 | E10: 1 | F10: 0 | G10: 1 | H10: =MEDIAN(C10:G10) -> 1 | I10: =IF(MAX(C10:G10)=MIN(C10:G10),"да","нет") -> нет | J10: модель (запасной выход)
A11: Доходы | B11: Чистые комиссионные доходы | C11: -1 | D11: -1 | E11: -1 | F11: 0 | G11: -1 | H11: =MEDIAN(C11:G11) -> -1 | I11: =IF(MAX(C11:G11)=MIN(C11:G11),"да","нет") -> нет | J11: модель (запасной выход)
A12: Доходы | B12: Чистая процентная маржа (NIM) | C12: 1 | D12: 1 | E12: 1 | F12: 0 | G12: 1 | H12: =MEDIAN(C12:G12) -> 1 | I12: =IF(MAX(C12:G12)=MIN(C12:G12),"да","нет") -> нет | J12: модель (запасной выход)
A13: Эффективность | B13: Операционные расходы | C13: 0 | D13: 0 | E13: 0 | F13: 0 | G13: 0 | H13: =MEDIAN(C13:G13) -> 0 | I13: =IF(MAX(C13:G13)=MIN(C13:G13),"да","нет") -> да | J13: код
A14: Эффективность | B14: Отношение расходов к доходам (CIR) | C14: 1 | D14: 1 | E14: 1 | F14: 1 | G14: 1 | H14: =MEDIAN(C14:G14) -> 1 | I14: =IF(MAX(C14:G14)=MIN(C14:G14),"да","нет") -> да | J14: модель (запасной выход)
A15: Риск | B15: Стоимость риска (CoR) | C15: 0 | D15: 0 | E15: 0 | F15: 0 | G15: 0 | H15: =MEDIAN(C15:G15) -> 0 | I15: =IF(MAX(C15:G15)=MIN(C15:G15),"да","нет") -> да | J15: код
A16: Риск | B16: Расходы на резервы | C16: 0 | D16: 0 | E16: 0 | F16: 0 | G16: 0 | H16: =MEDIAN(C16:G16) -> 0 | I16: =IF(MAX(C16:G16)=MIN(C16:G16),"да","нет") -> да | J16: код
A17: Риск | B17: Качество портфеля | C17: 1 | D17: 1 | E17: 1 | F17: 1 | G17: 1 | H17: =MEDIAN(C17:G17) -> 1 | I17: =IF(MAX(C17:G17)=MIN(C17:G17),"да","нет") -> да | J17: модель
... A29: Среда | B29: Тональность руководителя | C29: 2 | D29: 2 | E29: 2 | F29: 2 | G29: 2 | H29: =MEDIAN(C29:G29) -> 2 | I29: =IF(MAX(C29:G29)=MIN(C29:G29),"да","нет") -> да | J29: модель
B30: Сумма 24 оценок | C30: =SUM(C6:C29) -> 12 | D30: =SUM(D6:D29) -> 12 | E30: =SUM(E6:E29) -> 12 | F30: =SUM(F6:F29) -> 11 | G30: =SUM(G6:G29) -> 12 | H30: =SUM(H6:H29) -> 12
B31: Вывод (сумма > 12 — strong, < −12 — weak) | C31: =IF(C30>12,"strong",IF(C30<-12,"weak","mixed")) -> mixed | D31: =IF(D30>12,"strong",IF(D30<-12,"weak","mixed")) -> mixed | E31: =IF(E30>12,"strong",IF(E30<-12,"weak","mixed")) -> mixed | F31: =IF(F30>12,"strong",IF(F30<-12,"weak","mixed")) -> mixed | G31: =IF(G30>12,"strong",IF(G30<-12,"weak","mixed")) -> mixed | H31: =IF(H30>12,"strong",IF(H30<-12,"weak","mixed")) -> mixed
B33: Совпали во всех 5 прогонах (из 24) | C33: =COUNTIF(I6:I29,"да") -> 21
B34: Вывод одинаков во всех 5 прогонах | C34: =IF(COUNTIF(C31:G31,C31)=5,"да","нет") -> да
B35: Сумма по прогонам: минимум | C35: =MIN(C30:G30) -> 11
B36: Сумма по прогонам: максимум | C36: =MAX(C30:G30) -> 12

Sheet 2023_q2
A1: 2 кв. 2023 (6 мес.): оценки пяти прогонов
A2: Исходный файл: 2023_q2_ifrs__.pdf
A3: Прогоны отличаются только порядком показателей в запросе. Итог — медиана пяти оценок (совпадает с самым частым значением). «нет» в колонке I — хрупкая клетка, её нужно проверить человеку.
A5: Блок | B5: Показатель | C5: Прогон 1 | D5: Прогон 2 | E5: Прогон 3 | F5: Прогон 4 | G5: Прогон 5 | H5: Итог (медиана) | I5: Совпали во всех 5 | J5: Кто ставит
A6: Прибыльность | B6: Чистая прибыль | C6: 1 | D6: 0 | E6: 1 | F6: 1 | G6: 0 | H6: =MEDIAN(C6:G6) -> 1 | I6: =IF(MAX(C6:G6)=MIN(C6:G6),"да","нет") -> нет | J6: модель (запасной выход)
A7: Прибыльность | B7: Прибыль на акцию (EPS) | C7: 0 | D7: 0 | E7: 0 | F7: 0 | G7: 0 | H7: =MEDIAN(C7:G7) -> 0 | I7: =IF(MAX(C7:G7)=MIN(C7:G7),"да","нет") -> да | J7: код
A8: Прибыльность | B8: Рентабельность капитала (ROE) | C8: 1 | D8: 0 | E8: 0 | F8: 1 | G8: 0 | H8: =MEDIAN(C8:G8) -> 0 | I8: =IF(MAX(C8:G8)=MIN(C8:G8),"да","нет") -> нет | J8: код
A9: Прибыльность | B9: Прогноз менеджмента | C9: 1 | D9: 1 | E9: 1 | F9: 1 | G9: 1 | H9: =MEDIAN(C9:G9) -> 1 | I9: =IF(MAX(C9:G9)=MIN(C9:G9),"да","нет") -> да | J9: модель
A10: Доходы | B10: Чистые процентные доходы | C10: 1 | D10: 0 | E10: 1 | F10: 1 | G10: 0 | H10: =MEDIAN(C10:G10) -> 1 | I10: =IF(MAX(C10:G10)=MIN(C10:G10),"да","нет") -> нет | J10: модель (запасной выход)
A11: Доходы | B11: Чистые комиссионные доходы | C11: 1 | D11: 0 | E11: 0 | F11: 0 | G11: 0 | H11: =MEDIAN(C11:G11) -> 0 | I11: =IF(MAX(C11:G11)=MIN(C11:G11),"да","нет") -> нет | J11: код
A12: Доходы | B12: Чистая процентная маржа (NIM) | C12: 1 | D12: 0 | E12: 0 | F12: 0 | G12: 0 | H12: =MEDIAN(C12:G12) -> 0 | I12: =IF(MAX(C12:G12)=MIN(C12:G12),"да","нет") -> нет | J12: код
A13: Эффективность | B13: Операционные расходы | C13: 0 | D13: 0 | E13: 0 | F13: 0 | G13: 0 | H13: =MEDIAN(C13:G13) -> 0 | I13: =IF(MAX(C13:G13)=MIN(C13:G13),"да","нет") -> да | J13: код
A14: Эффективность | B14: Отношение расходов к доходам (CIR) | C14: 1 | D14: 0 | E14: 1 | F14: 1 | G14: -1 | H14: =MEDIAN(C14:G14) -> 1 | I14: =IF(MAX(C14:G14)=MIN(C14:G14),"да","нет") -> нет | J14: модель (запасной выход)
A15: Риск | B15: Стоимость риска (CoR) | C15: 0 | D15: 0 | E15: 0 | F15: 0 | G15: 0 | H15: =MEDIAN(C15:G15) -> 0 | I15: =IF(MAX(C15:G15)=MIN(C15:G15),"да","нет") -> да | J15: код
A16: Риск | B16: Расходы на резервы | C16: 0 | D16: 0 | E16: 0 | F16: 0 | G16: 0 | H16: =MEDIAN(C16:G16) -> 0 | I16: =IF(MAX(C16:G16)=MIN(C16:G16),"да","нет") -> да | J16: код
A17: Риск | B17: Качество портфеля | C17: 0 | D17: 0 | E17: 0 | F17: 0 | G17: 0 | H17: =MEDIAN(C17:G17) -> 0 | I17: =IF(MAX(C17:G17)=MIN(C17:G17),"да","нет") -> да | J17: модель
... A29: Среда | B29: Тональность руководителя | C29: 2 | D29: 1 | E29: 1 | F29: 1 | G29: 2 | H29: =MEDIAN(C29:G29) -> 1 | I29: =IF(MAX(C29:G29)=MIN(C29:G29),"да","нет") -> нет | J29: модель
B30: Сумма 24 оценок | C30: =SUM(C6:C29) -> 16 | D30: =SUM(D6:D29) -> 9 | E30: =SUM(E6:E29) -> 12 | F30: =SUM(F6:F29) -> 13 | G30: =SUM(G6:G29) -> 9 | H30: =SUM(H6:H29) -> 12
B31: Вывод (сумма > 12 — strong, < −12 — weak) | C31: =IF(C30>12,"strong",IF(C30<-12,"weak","mixed")) -> strong | D31: =IF(D30>12,"strong",IF(D30<-12,"weak","mixed")) -> mixed | E31: =IF(E30>12,"strong",IF(E30<-12,"weak","mixed")) -> mixed | F31: =IF(F30>12,"strong",IF(F30<-12,"weak","mixed")) -> strong | G31: =IF(G30>12,"strong",IF(G30<-12,"weak","mixed")) -> mixed | H31: =IF(H30>12,"strong",IF(H30<-12,"weak","mixed")) -> mixed
B33: Совпали во всех 5 прогонах (из 24) | C33: =COUNTIF(I6:I29,"да") -> 17
B34: Вывод одинаков во всех 5 прогонах | C34: =IF(COUNTIF(C31:G31,C31)=5,"да","нет") -> нет
B35: Сумма по прогонам: минимум | C35: =MIN(C30:G30) -> 9
B36: Сумма по прогонам: максимум | C36: =MAX(C30:G30) -> 16

Sheet 2023_q3
A1: 3 кв. 2023 (9 мес.): оценки пяти прогонов
A2: Исходный файл: 2023__q3__ifrs__.pdf
A3: Прогоны отличаются только порядком показателей в запросе. Итог — медиана пяти оценок (совпадает с самым частым значением). «нет» в колонке I — хрупкая клетка, её нужно проверить человеку.
A5: Блок | B5: Показатель | C5: Прогон 1 | D5: Прогон 2 | E5: Прогон 3 | F5: Прогон 4 | G5: Прогон 5 | H5: Итог (медиана) | I5: Совпали во всех 5 | J5: Кто ставит
A6: Прибыльность | B6: Чистая прибыль | C6: 0 | D6: 0 | E6: 0 | F6: 0 | G6: 0 | H6: =MEDIAN(C6:G6) -> 0 | I6: =IF(MAX(C6:G6)=MIN(C6:G6),"да","нет") -> да | J6: код
A7: Прибыльность | B7: Прибыль на акцию (EPS) | C7: 0 | D7: 0 | E7: 0 | F7: 0 | G7: 0 | H7: =MEDIAN(C7:G7) -> 0 | I7: =IF(MAX(C7:G7)=MIN(C7:G7),"да","нет") -> да | J7: код
A8: Прибыльность | B8: Рентабельность капитала (ROE) | C8: 0 | D8: 0 | E8: 0 | F8: 0 | G8: 0 | H8: =MEDIAN(C8:G8) -> 0 | I8: =IF(MAX(C8:G8)=MIN(C8:G8),"да","нет") -> да | J8: код
A9: Прибыльность | B9: Прогноз менеджмента | C9: 1 | D9: 1 | E9: 1 | F9: 1 | G9: 1 | H9: =MEDIAN(C9:G9) -> 1 | I9: =IF(MAX(C9:G9)=MIN(C9:G9),"да","нет") -> да | J9: модель
A10: Доходы | B10: Чистые процентные доходы | C10: 0 | D10: 0 | E10: 0 | F10: 0 | G10: 0 | H10: =MEDIAN(C10:G10) -> 0 | I10: =IF(MAX(C10:G10)=MIN(C10:G10),"да","нет") -> да | J10: код
A11: Доходы | B11: Чистые комиссионные доходы | C11: 0 | D11: 0 | E11: 0 | F11: 0 | G11: 0 | H11: =MEDIAN(C11:G11) -> 0 | I11: =IF(MAX(C11:G11)=MIN(C11:G11),"да","нет") -> да | J11: код
A12: Доходы | B12: Чистая процентная маржа (NIM) | C12: 0 | D12: 0 | E12: 0 | F12: 0 | G12: 0 | H12: =MEDIAN(C12:G12) -> 0 | I12: =IF(MAX(C12:G12)=MIN(C12:G12),"да","нет") -> да | J12: код
A13: Эффективность | B13: Операционные расходы | C13: 0 | D13: 0 | E13: 0 | F13: 0 | G13: 0 | H13: =MEDIAN(C13:G13) -> 0 | I13: =IF(MAX(C13:G13)=MIN(C13:G13),"да","нет") -> да | J13: код
A14: Эффективность | B14: Отношение расходов к доходам (CIR) | C14: 1 | D14: 0 | E14: 1 | F14: 1 | G14: 1 | H14: =MEDIAN(C14:G14) -> 1 | I14: =IF(MAX(C14:G14)=MIN(C14:G14),"да","нет") -> нет | J14: модель (запасной выход)
A15: Риск | B15: Стоимость риска (CoR) | C15: 0 | D15: 0 | E15: 0 | F15: 0 | G15: 0 | H15: =MEDIAN(C15:G15) -> 0 | I15: =IF(MAX(C15:G15)=MIN(C15:G15),"да","нет") -> да | J15: код
A16: Риск | B16: Расходы на резервы | C16: 0 | D16: 0 | E16: 0 | F16: 0 | G16: 0 | H16: =MEDIAN(C16:G16) -> 0 | I16: =IF(MAX(C16:G16)=MIN(C16:G16),"да","нет") -> да | J16: код
A17: Риск | B17: Качество портфеля | C17: 0 | D17: 0 | E17: 0 | F17: 0 | G17: 0 | H17: =MEDIAN(C17:G17) -> 0 | I17: =IF(MAX(C17:G17)=MIN(C17:G17),"да","нет") -> да | J17: модель
... A29: Среда | B29: Тональность руководителя | C29: 2 | D29: 2 | E29: 2 | F29: 2 | G29: 2 | H29: =MEDIAN(C29:G29) -> 2 | I29: =IF(MAX(C29:G29)=MIN(C29:G29),"да","нет") -> да | J29: модель
B30: Сумма 24 оценок | C30: =SUM(C6:C29) -> 12 | D30: =SUM(D6:D29) -> 11 | E30: =SUM(E6:E29) -> 12 | F30: =SUM(F6:F29) -> 12 | G30: =SUM(G6:G29) -> 12 | H30: =SUM(H6:H29) -> 12
B31: Вывод (сумма > 12 — strong, < −12 — weak) | C31: =IF(C30>12,"strong",IF(C30<-12,"weak","mixed")) -> mixed | D31: =IF(D30>12,"strong",IF(D30<-12,"weak","mixed")) -> mixed | E31: =IF(E30>12,"strong",IF(E30<-12,"weak","mixed")) -> mixed | F31: =IF(F30>12,"strong",IF(F30<-12,"weak","mixed")) -> mixed | G31: =IF(G30>12,"strong",IF(G30<-12,"weak","mixed")) -> mixed | H31: =IF(H30>12,"strong",IF(H30<-12,"weak","mixed")) -> mixed
B33: Совпали во всех 5 прогонах (из 24) | C33: =COUNTIF(I6:I29,"да") -> 23
B34: Вывод одинаков во всех 5 прогонах | C34: =IF(COUNTIF(C31:G31,C31)=5,"да","нет") -> да
B35: Сумма по прогонам: минимум | C35: =MIN(C30:G30) -> 11
B36: Сумма по прогонам: максимум | C36: =MAX(C30:G30) -> 12

Sheet 2023_q4
A1: 4 кв. и 12 мес. 2023: оценки пяти прогонов
A2: Исходный файл: 2023_ifrs_.pdf
A3: Прогоны отличаются только порядком показателей в запросе. Итог — медиана пяти оценок (совпадает с самым частым значением). «нет» в колонке I — хрупкая клетка, её нужно проверить человеку.
A5: Блок | B5: Показатель | C5: Прогон 1 | D5: Прогон 2 | E5: Прогон 3 | F5: Прогон 4 | G5: Прогон 5 | H5: Итог (медиана) | I5: Совпали во всех 5 | J5: Кто ставит
A6: Прибыльность | B6: Чистая прибыль | C6: 2 | D6: 2 | E6: 2 | F6: 2 | G6: 2 | H6: =MEDIAN(C6:G6) -> 2 | I6: =IF(MAX(C6:G6)=MIN(C6:G6),"да","нет") -> да | J6: код
A7: Прибыльность | B7: Прибыль на акцию (EPS) | C7: 2 | D7: 2 | E7: 2 | F7: 2 | G7: 2 | H7: =MEDIAN(C7:G7) -> 2 | I7: =IF(MAX(C7:G7)=MIN(C7:G7),"да","нет") -> да | J7: код
A8: Прибыльность | B8: Рентабельность капитала (ROE) | C8: 2 | D8: 2 | E8: 2 | F8: 2 | G8: 2 | H8: =MEDIAN(C8:G8) -> 2 | I8: =IF(MAX(C8:G8)=MIN(C8:G8),"да","нет") -> да | J8: код
A9: Прибыльность | B9: Прогноз менеджмента | C9: 0 | D9: 0 | E9: 0 | F9: 0 | G9: 0 | H9: =MEDIAN(C9:G9) -> 0 | I9: =IF(MAX(C9:G9)=MIN(C9:G9),"да","нет") -> да | J9: модель
A10: Доходы | B10: Чистые процентные доходы | C10: 2 | D10: 2 | E10: 2 | F10: 2 | G10: 2 | H10: =MEDIAN(C10:G10) -> 2 | I10: =IF(MAX(C10:G10)=MIN(C10:G10),"да","нет") -> да | J10: код
A11: Доходы | B11: Чистые комиссионные доходы | C11: 1 | D11: 1 | E11: 1 | F11: 1 | G11: 1 | H11: =MEDIAN(C11:G11) -> 1 | I11: =IF(MAX(C11:G11)=MIN(C11:G11),"да","нет") -> да | J11: код
A12: Доходы | B12: Чистая процентная маржа (NIM) | C12: 1 | D12: 1 | E12: 1 | F12: 1 | G12: 1 | H12: =MEDIAN(C12:G12) -> 1 | I12: =IF(MAX(C12:G12)=MIN(C12:G12),"да","нет") -> да | J12: код
A13: Эффективность | B13: Операционные расходы | C13: 2 | D13: 2 | E13: 2 | F13: 2 | G13: 2 | H13: =MEDIAN(C13:G13) -> 2 | I13: =IF(MAX(C13:G13)=MIN(C13:G13),"да","нет") -> да | J13: код
A14: Эффективность | B14: Отношение расходов к доходам (CIR) | C14: 2 | D14: 2 | E14: 2 | F14: 2 | G14: 2 | H14: =MEDIAN(C14:G14) -> 2 | I14: =IF(MAX(C14:G14)=MIN(C14:G14),"да","нет") -> да | J14: код
A15: Риск | B15: Стоимость риска (CoR) | C15: 2 | D15: 2 | E15: 2 | F15: 2 | G15: 2 | H15: =MEDIAN(C15:G15) -> 2 | I15: =IF(MAX(C15:G15)=MIN(C15:G15),"да","нет") -> да | J15: код
A16: Риск | B16: Расходы на резервы | C16: 2 | D16: 2 | E16: 2 | F16: 2 | G16: 2 | H16: =MEDIAN(C16:G16) -> 2 | I16: =IF(MAX(C16:G16)=MIN(C16:G16),"да","нет") -> да | J16: код
A17: Риск | B17: Качество портфеля | C17: 1 | D17: 1 | E17: 1 | F17: 1 | G17: 1 | H17: =MEDIAN(C17:G17) -> 1 | I17: =IF(MAX(C17:G17)=MIN(C17:G17),"да","нет") -> да | J17: модель
... A29: Среда | B29: Тональность руководителя | C29: 2 | D29: 2 | E29: 2 | F29: 2 | G29: 2 | H29: =MEDIAN(C29:G29) -> 2 | I29: =IF(MAX(C29:G29)=MIN(C29:G29),"да","нет") -> да | J29: модель
B30: Сумма 24 оценок | C30: =SUM(C6:C29) -> 30 | D30: =SUM(D6:D29) -> 31 | E30: =SUM(E6:E29) -> 29 | F30: =SUM(F6:F29) -> 29 | G30: =SUM(G6:G29) -> 29 | H30: =SUM(H6:H29) -> 29
B31: Вывод (сумма > 12 — strong, < −12 — weak) | C31: =IF(C30>12,"strong",IF(C30<-12,"weak","mixed")) -> strong | D31: =IF(D30>12,"strong",IF(D30<-12,"weak","mixed")) -> strong | E31: =IF(E30>12,"strong",IF(E30<-12,"weak","mixed")) -> strong | F31: =IF(F30>12,"strong",IF(F30<-12,"weak","mixed")) -> strong | G31: =IF(G30>12,"strong",IF(G30<-12,"weak","mixed")) -> strong | H31: =IF(H30>12,"strong",IF(H30<-12,"weak","mixed")) -> strong
B33: Совпали во всех 5 прогонах (из 24) | C33: =COUNTIF(I6:I29,"да") -> 22
B34: Вывод одинаков во всех 5 прогонах | C34: =IF(COUNTIF(C31:G31,C31)=5,"да","нет") -> да
B35: Сумма по прогонам: минимум | C35: =MIN(C30:G30) -> 29
B36: Сумма по прогонам: максимум | C36: =MAX(C30:G30) -> 31

Sheet 2024_q1
A1: 1 кв. 2024: оценки пяти прогонов
A2: Исходный файл: 2024_q1_xevivhwo_.pdf
A3: Прогоны отличаются только порядком показателей в запросе. Итог — медиана пяти оценок (совпадает с самым частым значением). «нет» в колонке I — хрупкая клетка, её нужно проверить человеку.
A5: Блок | B5: Показатель | C5: Прогон 1 | D5: Прогон 2 | E5: Прогон 3 | F5: Прогон 4 | G5: Прогон 5 | H5: Итог (медиана) | I5: Совпали во всех 5 | J5: Кто ставит
A6: Прибыльность | B6: Чистая прибыль | C6: 1 | D6: 1 | E6: 1 | F6: 1 | G6: 1 | H6: =MEDIAN(C6:G6) -> 1 | I6: =IF(MAX(C6:G6)=MIN(C6:G6),"да","нет") -> да | J6: код
A7: Прибыльность | B7: Прибыль на акцию (EPS) | C7: 1 | D7: 1 | E7: 1 | F7: 1 | G7: 1 | H7: =MEDIAN(C7:G7) -> 1 | I7: =IF(MAX(C7:G7)=MIN(C7:G7),"да","нет") -> да | J7: код
A8: Прибыльность | B8: Рентабельность капитала (ROE) | C8: -1 | D8: -1 | E8: -1 | F8: -1 | G8: -1 | H8: =MEDIAN(C8:G8) -> -1 | I8: =IF(MAX(C8:G8)=MIN(C8:G8),"да","нет") -> да | J8: код
A9: Прибыльность | B9: Прогноз менеджмента | C9: 0 | D9: 0 | E9: 0 | F9: 0 | G9: 0 | H9: =MEDIAN(C9:G9) -> 0 | I9: =IF(MAX(C9:G9)=MIN(C9:G9),"да","нет") -> да | J9: модель
A10: Доходы | B10: Чистые процентные доходы | C10: 2 | D10: 2 | E10: 2 | F10: 2 | G10: 2 | H10: =MEDIAN(C10:G10) -> 2 | I10: =IF(MAX(C10:G10)=MIN(C10:G10),"да","нет") -> да | J10: код
A11: Доходы | B11: Чистые комиссионные доходы | C11: 1 | D11: 1 | E11: 1 | F11: 1 | G11: 1 | H11: =MEDIAN(C11:G11) -> 1 | I11: =IF(MAX(C11:G11)=MIN(C11:G11),"да","нет") -> да | J11: код
A12: Доходы | B12: Чистая процентная маржа (NIM) | C12: 0 | D12: 0 | E12: 0 | F12: 0 | G12: 0 | H12: =MEDIAN(C12:G12) -> 0 | I12: =IF(MAX(C12:G12)=MIN(C12:G12),"да","нет") -> да | J12: код
A13: Эффективность | B13: Операционные расходы | C13: -2 | D13: -2 | E13: -2 | F13: -2 | G13: -2 | H13: =MEDIAN(C13:G13) -> -2 | I13: =IF(MAX(C13:G13)=MIN(C13:G13),"да","нет") -> да | J13: код
A14: Эффективность | B14: Отношение расходов к доходам (CIR) | C14: -2 | D14: -2 | E14: -2 | F14: -2 | G14: -2 | H14: =MEDIAN(C14:G14) -> -2 | I14: =IF(MAX(C14:G14)=MIN(C14:G14),"да","нет") -> да | J14: код
A15: Риск | B15: Стоимость риска (CoR) | C15: 2 | D15: 2 | E15: 2 | F15: 2 | G15: 2 | H15: =MEDIAN(C15:G15) -> 2 | I15: =IF(MAX(C15:G15)=MIN(C15:G15),"да","нет") -> да | J15: код
A16: Риск | B16: Расходы на резервы | C16: 2 | D16: 2 | E16: 2 | F16: 2 | G16: 2 | H16: =MEDIAN(C16:G16) -> 2 | I16: =IF(MAX(C16:G16)=MIN(C16:G16),"да","нет") -> да | J16: код
A17: Риск | B17: Качество портфеля | C17: 0 | D17: 1 | E17: 0 | F17: 1 | G17: 1 | H17: =MEDIAN(C17:G17) -> 1 | I17: =IF(MAX(C17:G17)=MIN(C17:G17),"да","нет") -> нет | J17: модель
... A29: Среда | B29: Тональность руководителя | C29: 1 | D29: 1 | E29: 1 | F29: 1 | G29: 1 | H29: =MEDIAN(C29:G29) -> 1 | I29: =IF(MAX(C29:G29)=MIN(C29:G29),"да","нет") -> да | J29: модель
B30: Сумма 24 оценок | C30: =SUM(C6:C29) -> 8 | D30: =SUM(D6:D29) -> 9 | E30: =SUM(E6:E29) -> 8 | F30: =SUM(F6:F29) -> 9 | G30: =SUM(G6:G29) -> 9 | H30: =SUM(H6:H29) -> 9
B31: Вывод (сумма > 12 — strong, < −12 — weak) | C31: =IF(C30>12,"strong",IF(C30<-12,"weak","mixed")) -> mixed | D31: =IF(D30>12,"strong",IF(D30<-12,"weak","mixed")) -> mixed | E31: =IF(E30>12,"strong",IF(E30<-12,"weak","mixed")) -> mixed | F31: =IF(F30>12,"strong",IF(F30<-12,"weak","mixed")) -> mixed | G31: =IF(G30>12,"strong",IF(G30<-12,"weak","mixed")) -> mixed | H31: =IF(H30>12,"strong",IF(H30<-12,"weak","mixed")) -> mixed
B33: Совпали во всех 5 прогонах (из 24) | C33: =COUNTIF(I6:I29,"да") -> 23
B34: Вывод одинаков во всех 5 прогонах | C34: =IF(COUNTIF(C31:G31,C31)=5,"да","нет") -> да
B35: Сумма по прогонам: минимум | C35: =MIN(C30:G30) -> 8
B36: Сумма по прогонам: максимум | C36: =MAX(C30:G30) -> 9

Sheet 2024_q2
A1: 2 кв. 2024 (6 мес.): оценки пяти прогонов
A2: Исходный файл: 2024_q2_najzxgya.pdf
A3: Прогоны отличаются только порядком показателей в запросе. Итог — медиана пяти оценок (совпадает с самым частым значением). «нет» в колонке I — хрупкая клетка, её нужно проверить человеку.
A5: Блок | B5: Показатель | C5: Прогон 1 | D5: Прогон 2 | E5: Прогон 3 | F5: Прогон 4 | G5: Прогон 5 | H5: Итог (медиана) | I5: Совпали во всех 5 | J5: Кто ставит
A6: Прибыльность | B6: Чистая прибыль | C6: 1 | D6: 1 | E6: 1 | F6: 1 | G6: 1 | H6: =MEDIAN(C6:G6) -> 1 | I6: =IF(MAX(C6:G6)=MIN(C6:G6),"да","нет") -> да | J6: код
A7: Прибыльность | B7: Прибыль на акцию (EPS) | C7: 1 | D7: 1 | E7: 1 | F7: 1 | G7: 1 | H7: =MEDIAN(C7:G7) -> 1 | I7: =IF(MAX(C7:G7)=MIN(C7:G7),"да","нет") -> да | J7: код
A8: Прибыльность | B8: Рентабельность капитала (ROE) | C8: 0 | D8: 0 | E8: 0 | F8: 0 | G8: 0 | H8: =MEDIAN(C8:G8) -> 0 | I8: =IF(MAX(C8:G8)=MIN(C8:G8),"да","нет") -> да | J8: код
A9: Прибыльность | B9: Прогноз менеджмента | C9: 1 | D9: 1 | E9: 1 | F9: 1 | G9: 1 | H9: =MEDIAN(C9:G9) -> 1 | I9: =IF(MAX(C9:G9)=MIN(C9:G9),"да","нет") -> да | J9: модель
A10: Доходы | B10: Чистые процентные доходы | C10: 2 | D10: 2 | E10: 2 | F10: 2 | G10: 2 | H10: =MEDIAN(C10:G10) -> 2 | I10: =IF(MAX(C10:G10)=MIN(C10:G10),"да","нет") -> да | J10: код
A11: Доходы | B11: Чистые комиссионные доходы | C11: 1 | D11: 1 | E11: 1 | F11: 1 | G11: 1 | H11: =MEDIAN(C11:G11) -> 1 | I11: =IF(MAX(C11:G11)=MIN(C11:G11),"да","нет") -> да | J11: код
A12: Доходы | B12: Чистая процентная маржа (NIM) | C12: 0 | D12: 0 | E12: 0 | F12: 0 | G12: 0 | H12: =MEDIAN(C12:G12) -> 0 | I12: =IF(MAX(C12:G12)=MIN(C12:G12),"да","нет") -> да | J12: код
A13: Эффективность | B13: Операционные расходы | C13: -2 | D13: -2 | E13: -2 | F13: -2 | G13: -2 | H13: =MEDIAN(C13:G13) -> -2 | I13: =IF(MAX(C13:G13)=MIN(C13:G13),"да","нет") -> да | J13: код
A14: Эффективность | B14: Отношение расходов к доходам (CIR) | C14: -2 | D14: -2 | E14: -2 | F14: -2 | G14: -2 | H14: =MEDIAN(C14:G14) -> -2 | I14: =IF(MAX(C14:G14)=MIN(C14:G14),"да","нет") -> да | J14: код
A15: Риск | B15: Стоимость риска (CoR) | C15: 1 | D15: 1 | E15: 1 | F15: 1 | G15: 1 | H15: =MEDIAN(C15:G15) -> 1 | I15: =IF(MAX(C15:G15)=MIN(C15:G15),"да","нет") -> да | J15: код
A16: Риск | B16: Расходы на резервы | C16: 1 | D16: 1 | E16: 1 | F16: 1 | G16: 1 | H16: =MEDIAN(C16:G16) -> 1 | I16: =IF(MAX(C16:G16)=MIN(C16:G16),"да","нет") -> да | J16: код
A17: Риск | B17: Качество портфеля | C17: 1 | D17: 1 | E17: 0 | F17: 1 | G17: 1 | H17: =MEDIAN(C17:G17) -> 1 | I17: =IF(MAX(C17:G17)=MIN(C17:G17),"да","нет") -> нет | J17: модель
... A29: Среда | B29: Тональность руководителя | C29: 1 | D29: 1 | E29: 1 | F29: 1 | G29: 1 | H29: =MEDIAN(C29:G29) -> 1 | I29: =IF(MAX(C29:G29)=MIN(C29:G29),"да","нет") -> да | J29: модель
B30: Сумма 24 оценок | C30: =SUM(C6:C29) -> 15 | D30: =SUM(D6:D29) -> 13 | E30: =SUM(E6:E29) -> 13 | F30: =SUM(F6:F29) -> 14 | G30: =SUM(G6:G29) -> 14 | H30: =SUM(H6:H29) -> 14
B31: Вывод (сумма > 12 — strong, < −12 — weak) | C31: =IF(C30>12,"strong",IF(C30<-12,"weak","mixed")) -> strong | D31: =IF(D30>12,"strong",IF(D30<-12,"weak","mixed")) -> strong | E31: =IF(E30>12,"strong",IF(E30<-12,"weak","mixed")) -> strong | F31: =IF(F30>12,"strong",IF(F30<-12,"weak","mixed")) -> strong | G31: =IF(G30>12,"strong",IF(G30<-12,"weak","mixed")) -> strong | H31: =IF(H30>12,"strong",IF(H30<-12,"weak","mixed")) -> strong
B33: Совпали во всех 5 прогонах (из 24) | C33: =COUNTIF(I6:I29,"да") -> 22
B34: Вывод одинаков во всех 5 прогонах | C34: =IF(COUNTIF(C31:G31,C31)=5,"да","нет") -> да
B35: Сумма по прогонам: минимум | C35: =MIN(C30:G30) -> 13
B36: Сумма по прогонам: максимум | C36: =MAX(C30:G30) -> 15

Sheet 2024_q3
A1: 3 кв. 2024 (9 мес.): оценки пяти прогонов
A2: Исходный файл: q3_hblsyjgb_2024.pdf
A3: Прогоны отличаются только порядком показателей в запросе. Итог — медиана пяти оценок (совпадает с самым частым значением). «нет» в колонке I — хрупкая клетка, её нужно проверить человеку.
A5: Блок | B5: Показатель | C5: Прогон 1 | D5: Прогон 2 | E5: Прогон 3 | F5: Прогон 4 | G5: Прогон 5 | H5: Итог (медиана) | I5: Совпали во всех 5 | J5: Кто ставит
A6: Прибыльность | B6: Чистая прибыль | C6: 0 | D6: 0 | E6: 0 | F6: 0 | G6: 0 | H6: =MEDIAN(C6:G6) -> 0 | I6: =IF(MAX(C6:G6)=MIN(C6:G6),"да","нет") -> да | J6: код
A7: Прибыльность | B7: Прибыль на акцию (EPS) | C7: 0 | D7: 0 | E7: 0 | F7: 0 | G7: 0 | H7: =MEDIAN(C7:G7) -> 0 | I7: =IF(MAX(C7:G7)=MIN(C7:G7),"да","нет") -> да | J7: код
A8: Прибыльность | B8: Рентабельность капитала (ROE) | C8: -2 | D8: -2 | E8: -2 | F8: -2 | G8: -2 | H8: =MEDIAN(C8:G8) -> -2 | I8: =IF(MAX(C8:G8)=MIN(C8:G8),"да","нет") -> да | J8: код
A9: Прибыльность | B9: Прогноз менеджмента | C9: 0 | D9: 0 | E9: 0 | F9: 0 | G9: 0 | H9: =MEDIAN(C9:G9) -> 0 | I9: =IF(MAX(C9:G9)=MIN(C9:G9),"да","нет") -> да | J9: модель
A10: Доходы | B10: Чистые процентные доходы | C10: 1 | D10: 1 | E10: 1 | F10: 1 | G10: 1 | H10: =MEDIAN(C10:G10) -> 1 | I10: =IF(MAX(C10:G10)=MIN(C10:G10),"да","нет") -> да | J10: код
A11: Доходы | B11: Чистые комиссионные доходы | C11: 1 | D11: 1 | E11: 1 | F11: 1 | G11: 1 | H11: =MEDIAN(C11:G11) -> 1 | I11: =IF(MAX(C11:G11)=MIN(C11:G11),"да","нет") -> да | J11: код
A12: Доходы | B12: Чистая процентная маржа (NIM) | C12: 0 | D12: 0 | E12: 0 | F12: 0 | G12: 0 | H12: =MEDIAN(C12:G12) -> 0 | I12: =IF(MAX(C12:G12)=MIN(C12:G12),"да","нет") -> да | J12: код
A13: Эффективность | B13: Операционные расходы | C13: 1 | D13: 1 | E13: 1 | F13: 1 | G13: 1 | H13: =MEDIAN(C13:G13) -> 1 | I13: =IF(MAX(C13:G13)=MIN(C13:G13),"да","нет") -> да | J13: код
A14: Эффективность | B14: Отношение расходов к доходам (CIR) | C14: 1 | D14: 1 | E14: 1 | F14: 1 | G14: 1 | H14: =MEDIAN(C14:G14) -> 1 | I14: =IF(MAX(C14:G14)=MIN(C14:G14),"да","нет") -> да | J14: код
A15: Риск | B15: Стоимость риска (CoR) | C15: -2 | D15: -2 | E15: 0 | F15: -2 | G15: -2 | H15: =MEDIAN(C15:G15) -> -2 | I15: =IF(MAX(C15:G15)=MIN(C15:G15),"да","нет") -> нет | J15: код
A16: Риск | B16: Расходы на резервы | C16: -2 | D16: -2 | E16: -2 | F16: -2 | G16: -2 | H16: =MEDIAN(C16:G16) -> -2 | I16: =IF(MAX(C16:G16)=MIN(C16:G16),"да","нет") -> да | J16: код
A17: Риск | B17: Качество портфеля | C17: 0 | D17: 0 | E17: 0 | F17: 0 | G17: 0 | H17: =MEDIAN(C17:G17) -> 0 | I17: =IF(MAX(C17:G17)=MIN(C17:G17),"да","нет") -> да | J17: модель
... A29: Среда | B29: Тональность руководителя | C29: 1 | D29: -1 | E29: 0 | F29: 1 | G29: 1 | H29: =MEDIAN(C29:G29) -> 1 | I29: =IF(MAX(C29:G29)=MIN(C29:G29),"да","нет") -> нет | J29: модель
B30: Сумма 24 оценок | C30: =SUM(C6:C29) -> 4 | D30: =SUM(D6:D29) -> 2 | E30: =SUM(E6:E29) -> 5 | F30: =SUM(F6:F29) -> 4 | G30: =SUM(G6:G29) -> 3 | H30: =SUM(H6:H29) -> 4
B31: Вывод (сумма > 12 — strong, < −12 — weak) | C31: =IF(C30>12,"strong",IF(C30<-12,"weak","mixed")) -> mixed | D31: =IF(D30>12,"strong",IF(D30<-12,"weak","mixed")) -> mixed | E31: =IF(E30>12,"strong",IF(E30<-12,"weak","mixed")) -> mixed | F31: =IF(F30>12,"strong",IF(F30<-12,"weak","mixed")) -> mixed | G31: =IF(G30>12,"strong",IF(G30<-12,"weak","mixed")) -> mixed | H31: =IF(H30>12,"strong",IF(H30<-12,"weak","mixed")) -> mixed
B33: Совпали во всех 5 прогонах (из 24) | C33: =COUNTIF(I6:I29,"да") -> 21
B34: Вывод одинаков во всех 5 прогонах | C34: =IF(COUNTIF(C31:G31,C31)=5,"да","нет") -> да
B35: Сумма по прогонам: минимум | C35: =MIN(C30:G30) -> 2
B36: Сумма по прогонам: максимум | C36: =MAX(C30:G30) -> 5

Sheet 2024_q4
A1: 4 кв. и 12 мес. 2024: оценки пяти прогонов
A2: Исходный файл: results_q4_qx5ln89k_2024.pdf
A3: Прогоны отличаются только порядком показателей в запросе. Итог — медиана пяти оценок (совпадает с самым частым значением). «нет» в колонке I — хрупкая клетка, её нужно проверить человеку.
A5: Блок | B5: Показатель | C5: Прогон 1 | D5: Прогон 2 | E5: Прогон 3 | F5: Прогон 4 | G5: Прогон 5 | H5: Итог (медиана) | I5: Совпали во всех 5 | J5: Кто ставит
A6: Прибыльность | B6: Чистая прибыль | C6: 0 | D6: 0 | E6: 0 | F6: 0 | G6: 0 | H6: =MEDIAN(C6:G6) -> 0 | I6: =IF(MAX(C6:G6)=MIN(C6:G6),"да","нет") -> да | J6: код
A7: Прибыльность | B7: Прибыль на акцию (EPS) | C7: 0 | D7: 0 | E7: 0 | F7: 0 | G7: 0 | H7: =MEDIAN(C7:G7) -> 0 | I7: =IF(MAX(C7:G7)=MIN(C7:G7),"да","нет") -> да | J7: код
A8: Прибыльность | B8: Рентабельность капитала (ROE) | C8: -2 | D8: -2 | E8: -2 | F8: -2 | G8: -2 | H8: =MEDIAN(C8:G8) -> -2 | I8: =IF(MAX(C8:G8)=MIN(C8:G8),"да","нет") -> да | J8: код
A9: Прибыльность | B9: Прогноз менеджмента | C9: 1 | D9: 1 | E9: 1 | F9: 1 | G9: 1 | H9: =MEDIAN(C9:G9) -> 1 | I9: =IF(MAX(C9:G9)=MIN(C9:G9),"да","нет") -> да | J9: модель
A10: Доходы | B10: Чистые процентные доходы | C10: 1 | D10: 1 | E10: 1 | F10: 1 | G10: 1 | H10: =MEDIAN(C10:G10) -> 1 | I10: =IF(MAX(C10:G10)=MIN(C10:G10),"да","нет") -> да | J10: код
A11: Доходы | B11: Чистые комиссионные доходы | C11: 1 | D11: 1 | E11: 1 | F11: 1 | G11: 1 | H11: =MEDIAN(C11:G11) -> 1 | I11: =IF(MAX(C11:G11)=MIN(C11:G11),"да","нет") -> да | J11: код
A12: Доходы | B12: Чистая процентная маржа (NIM) | C12: -1 | D12: -1 | E12: -1 | F12: -1 | G12: -1 | H12: =MEDIAN(C12:G12) -> -1 | I12: =IF(MAX(C12:G12)=MIN(C12:G12),"да","нет") -> да | J12: код
A13: Эффективность | B13: Операционные расходы | C13: 1 | D13: 1 | E13: 1 | F13: 1 | G13: 1 | H13: =MEDIAN(C13:G13) -> 1 | I13: =IF(MAX(C13:G13)=MIN(C13:G13),"да","нет") -> да | J13: код
A14: Эффективность | B14: Отношение расходов к доходам (CIR) | C14: 1 | D14: 1 | E14: 1 | F14: 1 | G14: 1 | H14: =MEDIAN(C14:G14) -> 1 | I14: =IF(MAX(C14:G14)=MIN(C14:G14),"да","нет") -> да | J14: код
A15: Риск | B15: Стоимость риска (CoR) | C15: -2 | D15: -2 | E15: -2 | F15: -2 | G15: -2 | H15: =MEDIAN(C15:G15) -> -2 | I15: =IF(MAX(C15:G15)=MIN(C15:G15),"да","нет") -> да | J15: код
A16: Риск | B16: Расходы на резервы | C16: -1 | D16: -2 | E16: -2 | F16: -1 | G16: -2 | H16: =MEDIAN(C16:G16) -> -2 | I16: =IF(MAX(C16:G16)=MIN(C16:G16),"да","нет") -> нет | J16: код
A17: Риск | B17: Качество портфеля | C17: -1 | D17: 0 | E17: 0 | F17: -1 | G17: -1 | H17: =MEDIAN(C17:G17) -> -1 | I17: =IF(MAX(C17:G17)=MIN(C17:G17),"да","нет") -> нет | J17: модель
... A29: Среда | B29: Тональность руководителя | C29: 0 | D29: 0 | E29: 0 | F29: 0 | G29: 0 | H29: =MEDIAN(C29:G29) -> 0 | I29: =IF(MAX(C29:G29)=MIN(C29:G29),"да","нет") -> да | J29: модель
B30: Сумма 24 оценок | C30: =SUM(C6:C29) -> 4 | D30: =SUM(D6:D29) -> 4 | E30: =SUM(E6:E29) -> 4 | F30: =SUM(F6:F29) -> 3 | G30: =SUM(G6:G29) -> 3 | H30: =SUM(H6:H29) -> 3
B31: Вывод (сумма > 12 — strong, < −12 — weak) | C31: =IF(C30>12,"strong",IF(C30<-12,"weak","mixed")) -> mixed | D31: =IF(D30>12,"strong",IF(D30<-12,"weak","mixed")) -> mixed | E31: =IF(E30>12,"strong",IF(E30<-12,"weak","mixed")) -> mixed | F31: =IF(F30>12,"strong",IF(F30<-12,"weak","mixed")) -> mixed | G31: =IF(G30>12,"strong",IF(G30<-12,"weak","mixed")) -> mixed | H31: =IF(H30>12,"strong",IF(H30<-12,"weak","mixed")) -> mixed
B33: Совпали во всех 5 прогонах (из 24) | C33: =COUNTIF(I6:I29,"да") -> 21
B34: Вывод одинаков во всех 5 прогонах | C34: =IF(COUNTIF(C31:G31,C31)=5,"да","нет") -> да
B35: Сумма по прогонам: минимум | C35: =MIN(C30:G30) -> 3
B36: Сумма по прогонам: максимум | C36: =MAX(C30:G30) -> 4

Sheet 2025_q1
A1: 1 кв. 2025: оценки пяти прогонов
A2: Исходный файл: q1_1mx9mq2c_2025year_results_ifrs.pdf
A3: Прогоны отличаются только порядком показателей в запросе. Итог — медиана пяти оценок (совпадает с самым частым значением). «нет» в колонке I — хрупкая клетка, её нужно проверить человеку.
A5: Блок | B5: Показатель | C5: Прогон 1 | D5: Прогон 2 | E5: Прогон 3 | F5: Прогон 4 | G5: Прогон 5 | H5: Итог (медиана) | I5: Совпали во всех 5 | J5: Кто ставит
A6: Прибыльность | B6: Чистая прибыль | C6: 1 | D6: 1 | E6: 1 | F6: 1 | G6: 1 | H6: =MEDIAN(C6:G6) -> 1 | I6: =IF(MAX(C6:G6)=MIN(C6:G6),"да","нет") -> да | J6: код
A7: Прибыльность | B7: Прибыль на акцию (EPS) | C7: 1 | D7: 1 | E7: 1 | F7: 1 | G7: 1 | H7: =MEDIAN(C7:G7) -> 1 | I7: =IF(MAX(C7:G7)=MIN(C7:G7),"да","нет") -> да | J7: код
A8: Прибыльность | B8: Рентабельность капитала (ROE) | C8: 0 | D8: 0 | E8: 0 | F8: 0 | G8: 0 | H8: =MEDIAN(C8:G8) -> 0 | I8: =IF(MAX(C8:G8)=MIN(C8:G8),"да","нет") -> да | J8: код
A9: Прибыльность | B9: Прогноз менеджмента | C9: 0 | D9: 0 | E9: 0 | F9: 0 | G9: 0 | H9: =MEDIAN(C9:G9) -> 0 | I9: =IF(MAX(C9:G9)=MIN(C9:G9),"да","нет") -> да | J9: модель
A10: Доходы | B10: Чистые процентные доходы | C10: 2 | D10: 2 | E10: 2 | F10: 2 | G10: 2 | H10: =MEDIAN(C10:G10) -> 2 | I10: =IF(MAX(C10:G10)=MIN(C10:G10),"да","нет") -> да | J10: код
A11: Доходы | B11: Чистые комиссионные доходы | C11: 1 | D11: 1 | E11: 1 | F11: 1 | G11: 1 | H11: =MEDIAN(C11:G11) -> 1 | I11: =IF(MAX(C11:G11)=MIN(C11:G11),"да","нет") -> да | J11: код
A12: Доходы | B12: Чистая процентная маржа (NIM) | C12: 0 | D12: 0 | E12: 0 | F12: 0 | G12: 0 | H12: =MEDIAN(C12:G12) -> 0 | I12: =IF(MAX(C12:G12)=MIN(C12:G12),"да","нет") -> да | J12: код
A13: Эффективность | B13: Операционные расходы | C13: 1 | D13: 1 | E13: 1 | F13: 1 | G13: 1 | H13: =MEDIAN(C13:G13) -> 1 | I13: =IF(MAX(C13:G13)=MIN(C13:G13),"да","нет") -> да | J13: код
A14: Эффективность | B14: Отношение расходов к доходам (CIR) | C14: 1 | D14: 1 | E14: 1 | F14: 1 | G14: 1 | H14: =MEDIAN(C14:G14) -> 1 | I14: =IF(MAX(C14:G14)=MIN(C14:G14),"да","нет") -> да | J14: код
A15: Риск | B15: Стоимость риска (CoR) | C15: -2 | D15: -2 | E15: -2 | F15: -2 | G15: -2 | H15: =MEDIAN(C15:G15) -> -2 | I15: =IF(MAX(C15:G15)=MIN(C15:G15),"да","нет") -> да | J15: код
A16: Риск | B16: Расходы на резервы | C16: -2 | D16: -2 | E16: -2 | F16: -2 | G16: -2 | H16: =MEDIAN(C16:G16) -> -2 | I16: =IF(MAX(C16:G16)=MIN(C16:G16),"да","нет") -> да | J16: код
A17: Риск | B17: Качество портфеля | C17: -1 | D17: -1 | E17: -1 | F17: -1 | G17: -1 | H17: =MEDIAN(C17:G17) -> -1 | I17: =IF(MAX(C17:G17)=MIN(C17:G17),"да","нет") -> да | J17: модель
... A29: Среда | B29: Тональность руководителя | C29: 1 | D29: 1 | E29: 1 | F29: 1 | G29: 1 | H29: =MEDIAN(C29:G29) -> 1 | I29: =IF(MAX(C29:G29)=MIN(C29:G29),"да","нет") -> да | J29: модель
B30: Сумма 24 оценок | C30: =SUM(C6:C29) -> 6 | D30: =SUM(D6:D29) -> 6 | E30: =SUM(E6:E29) -> 6 | F30: =SUM(F6:F29) -> 6 | G30: =SUM(G6:G29) -> 6 | H30: =SUM(H6:H29) -> 6
B31: Вывод (сумма > 12 — strong, < −12 — weak) | C31: =IF(C30>12,"strong",IF(C30<-12,"weak","mixed")) -> mixed | D31: =IF(D30>12,"strong",IF(D30<-12,"weak","mixed")) -> mixed | E31: =IF(E30>12,"strong",IF(E30<-12,"weak","mixed")) -> mixed | F31: =IF(F30>12,"strong",IF(F30<-12,"weak","mixed")) -> mixed | G31: =IF(G30>12,"strong",IF(G30<-12,"weak","mixed")) -> mixed | H31: =IF(H30>12,"strong",IF(H30<-12,"weak","mixed")) -> mixed
B33: Совпали во всех 5 прогонах (из 24) | C33: =COUNTIF(I6:I29,"да") -> 24
B34: Вывод одинаков во всех 5 прогонах | C34: =IF(COUNTIF(C31:G31,C31)=5,"да","нет") -> да
B35: Сумма по прогонам: минимум | C35: =MIN(C30:G30) -> 6
B36: Сумма по прогонам: максимум | C36: =MAX(C30:G30) -> 6

Sheet 2025_q2
A1: 2 кв. 2025 (6 мес.): оценки пяти прогонов
A2: Исходный файл: ifrs_results_q2_ry5mjx7g_2025.pdf
A3: Прогоны отличаются только порядком показателей в запросе. Итог — медиана пяти оценок (совпадает с самым частым значением). «нет» в колонке I — хрупкая клетка, её нужно проверить человеку.
A5: Блок | B5: Показатель | C5: Прогон 1 | D5: Прогон 2 | E5: Прогон 3 | F5: Прогон 4 | G5: Прогон 5 | H5: Итог (медиана) | I5: Совпали во всех 5 | J5: Кто ставит
A6: Прибыльность | B6: Чистая прибыль | C6: 0 | D6: 0 | E6: 0 | F6: 0 | G6: 0 | H6: =MEDIAN(C6:G6) -> 0 | I6: =IF(MAX(C6:G6)=MIN(C6:G6),"да","нет") -> да | J6: код
A7: Прибыльность | B7: Прибыль на акцию (EPS) | C7: 0 | D7: 0 | E7: 0 | F7: 0 | G7: 0 | H7: =MEDIAN(C7:G7) -> 0 | I7: =IF(MAX(C7:G7)=MIN(C7:G7),"да","нет") -> да | J7: код
A8: Прибыльность | B8: Рентабельность капитала (ROE) | C8: -2 | D8: -2 | E8: -2 | F8: -2 | G8: -2 | H8: =MEDIAN(C8:G8) -> -2 | I8: =IF(MAX(C8:G8)=MIN(C8:G8),"да","нет") -> да | J8: код
A9: Прибыльность | B9: Прогноз менеджмента | C9: 0 | D9: 0 | E9: 0 | F9: 0 | G9: 0 | H9: =MEDIAN(C9:G9) -> 0 | I9: =IF(MAX(C9:G9)=MIN(C9:G9),"да","нет") -> да | J9: модель
A10: Доходы | B10: Чистые процентные доходы | C10: 2 | D10: 2 | E10: 2 | F10: 2 | G10: 2 | H10: =MEDIAN(C10:G10) -> 2 | I10: =IF(MAX(C10:G10)=MIN(C10:G10),"да","нет") -> да | J10: код
A11: Доходы | B11: Чистые комиссионные доходы | C11: -1 | D11: -1 | E11: -1 | F11: -1 | G11: -1 | H11: =MEDIAN(C11:G11) -> -1 | I11: =IF(MAX(C11:G11)=MIN(C11:G11),"да","нет") -> да | J11: код
A12: Доходы | B12: Чистая процентная маржа (NIM) | C12: 1 | D12: 1 | E12: 1 | F12: 1 | G12: 1 | H12: =MEDIAN(C12:G12) -> 1 | I12: =IF(MAX(C12:G12)=MIN(C12:G12),"да","нет") -> да | J12: код
A13: Эффективность | B13: Операционные расходы | C13: 1 | D13: 1 | E13: 1 | F13: 1 | G13: 1 | H13: =MEDIAN(C13:G13) -> 1 | I13: =IF(MAX(C13:G13)=MIN(C13:G13),"да","нет") -> да | J13: код
A14: Эффективность | B14: Отношение расходов к доходам (CIR) | C14: 1 | D14: 1 | E14: 1 | F14: 1 | G14: 1 | H14: =MEDIAN(C14:G14) -> 1 | I14: =IF(MAX(C14:G14)=MIN(C14:G14),"да","нет") -> да | J14: код
A15: Риск | B15: Стоимость риска (CoR) | C15: -2 | D15: -2 | E15: -2 | F15: -2 | G15: -2 | H15: =MEDIAN(C15:G15) -> -2 | I15: =IF(MAX(C15:G15)=MIN(C15:G15),"да","нет") -> да | J15: код
A16: Риск | B16: Расходы на резервы | C16: -2 | D16: -2 | E16: -2 | F16: -2 | G16: -2 | H16: =MEDIAN(C16:G16) -> -2 | I16: =IF(MAX(C16:G16)=MIN(C16:G16),"да","нет") -> да | J16: код
A17: Риск | B17: Качество портфеля | C17: -1 | D17: -1 | E17: -1 | F17: -1 | G17: -1 | H17: =MEDIAN(C17:G17) -> -1 | I17: =IF(MAX(C17:G17)=MIN(C17:G17),"да","нет") -> да | J17: модель
... A29: Среда | B29: Тональность руководителя | C29: 1 | D29: 1 | E29: 1 | F29: 1 | G29: 1 | H29: =MEDIAN(C29:G29) -> 1 | I29: =IF(MAX(C29:G29)=MIN(C29:G29),"да","нет") -> да | J29: модель
B30: Сумма 24 оценок | C30: =SUM(C6:C29) -> 4 | D30: =SUM(D6:D29) -> 5 | E30: =SUM(E6:E29) -> 5 | F30: =SUM(F6:F29) -> 5 | G30: =SUM(G6:G29) -> 5 | H30: =SUM(H6:H29) -> 5
B31: Вывод (сумма > 12 — strong, < −12 — weak) | C31: =IF(C30>12,"strong",IF(C30<-12,"weak","mixed")) -> mixed | D31: =IF(D30>12,"strong",IF(D30<-12,"weak","mixed")) -> mixed | E31: =IF(E30>12,"strong",IF(E30<-12,"weak","mixed")) -> mixed | F31: =IF(F30>12,"strong",IF(F30<-12,"weak","mixed")) -> mixed | G31: =IF(G30>12,"strong",IF(G30<-12,"weak","mixed")) -> mixed | H31: =IF(H30>12,"strong",IF(H30<-12,"weak","mixed")) -> mixed
B33: Совпали во всех 5 прогонах (из 24) | C33: =COUNTIF(I6:I29,"да") -> 23
B34: Вывод одинаков во всех 5 прогонах | C34: =IF(COUNTIF(C31:G31,C31)=5,"да","нет") -> да
B35: Сумма по прогонам: минимум | C35: =MIN(C30:G30) -> 4
B36: Сумма по прогонам: максимум | C36: =MAX(C30:G30) -> 5

Sheet 2025_q3
A1: 3 кв. 2025 (9 мес.): оценки пяти прогонов
A2: Исходный файл: ifrs_results_q3_4gpw5f9j_2025.pdf
A3: Прогоны отличаются только порядком показателей в запросе. Итог — медиана пяти оценок (совпадает с самым частым значением). «нет» в колонке I — хрупкая клетка, её нужно проверить человеку.
A5: Блок | B5: Показатель | C5: Прогон 1 | D5: Прогон 2 | E5: Прогон 3 | F5: Прогон 4 | G5: Прогон 5 | H5: Итог (медиана) | I5: Совпали во всех 5 | J5: Кто ставит
A6: Прибыльность | B6: Чистая прибыль | C6: 1 | D6: 1 | E6: 1 | F6: 1 | G6: 1 | H6: =MEDIAN(C6:G6) -> 1 | I6: =IF(MAX(C6:G6)=MIN(C6:G6),"да","нет") -> да | J6: код
A7: Прибыльность | B7: Прибыль на акцию (EPS) | C7: 1 | D7: 1 | E7: 1 | F7: 1 | G7: 1 | H7: =MEDIAN(C7:G7) -> 1 | I7: =IF(MAX(C7:G7)=MIN(C7:G7),"да","нет") -> да | J7: код
A8: Прибыльность | B8: Рентабельность капитала (ROE) | C8: -2 | D8: -2 | E8: -2 | F8: -2 | G8: -2 | H8: =MEDIAN(C8:G8) -> -2 | I8: =IF(MAX(C8:G8)=MIN(C8:G8),"да","нет") -> да | J8: код
A9: Прибыльность | B9: Прогноз менеджмента | C9: 0 | D9: 0 | E9: 0 | F9: 0 | G9: 0 | H9: =MEDIAN(C9:G9) -> 0 | I9: =IF(MAX(C9:G9)=MIN(C9:G9),"да","нет") -> да | J9: модель
A10: Доходы | B10: Чистые процентные доходы | C10: 2 | D10: 2 | E10: 2 | F10: 2 | G10: 2 | H10: =MEDIAN(C10:G10) -> 2 | I10: =IF(MAX(C10:G10)=MIN(C10:G10),"да","нет") -> да | J10: код
A11: Доходы | B11: Чистые комиссионные доходы | C11: 0 | D11: 0 | E11: 0 | F11: 0 | G11: 0 | H11: =MEDIAN(C11:G11) -> 0 | I11: =IF(MAX(C11:G11)=MIN(C11:G11),"да","нет") -> да | J11: код
A12: Доходы | B12: Чистая процентная маржа (NIM) | C12: 1 | D12: 1 | E12: 1 | F12: 1 | G12: 1 | H12: =MEDIAN(C12:G12) -> 1 | I12: =IF(MAX(C12:G12)=MIN(C12:G12),"да","нет") -> да | J12: код
A13: Эффективность | B13: Операционные расходы | C13: 0 | D13: 0 | E13: 0 | F13: 0 | G13: 0 | H13: =MEDIAN(C13:G13) -> 0 | I13: =IF(MAX(C13:G13)=MIN(C13:G13),"да","нет") -> да | J13: код
A14: Эффективность | B14: Отношение расходов к доходам (CIR) | C14: 0 | D14: 0 | E14: 0 | F14: 0 | G14: 0 | H14: =MEDIAN(C14:G14) -> 0 | I14: =IF(MAX(C14:G14)=MIN(C14:G14),"да","нет") -> да | J14: код
A15: Риск | B15: Стоимость риска (CoR) | C15: -1 | D15: -1 | E15: -1 | F15: -1 | G15: -1 | H15: =MEDIAN(C15:G15) -> -1 | I15: =IF(MAX(C15:G15)=MIN(C15:G15),"да","нет") -> да | J15: код
A16: Риск | B16: Расходы на резервы | C16: -2 | D16: -2 | E16: -2 | F16: -2 | G16: -2 | H16: =MEDIAN(C16:G16) -> -2 | I16: =IF(MAX(C16:G16)=MIN(C16:G16),"да","нет") -> да | J16: код
A17: Риск | B17: Качество портфеля | C17: -1 | D17: -1 | E17: -1 | F17: -1 | G17: -1 | H17: =MEDIAN(C17:G17) -> -1 | I17: =IF(MAX(C17:G17)=MIN(C17:G17),"да","нет") -> да | J17: модель
... A29: Среда | B29: Тональность руководителя | C29: 1 | D29: 1 | E29: 1 | F29: 1 | G29: 1 | H29: =MEDIAN(C29:G29) -> 1 | I29: =IF(MAX(C29:G29)=MIN(C29:G29),"да","нет") -> да | J29: модель
B30: Сумма 24 оценок | C30: =SUM(C6:C29) -> 4 | D30: =SUM(D6:D29) -> 4 | E30: =SUM(E6:E29) -> 4 | F30: =SUM(F6:F29) -> 4 | G30: =SUM(G6:G29) -> 4 | H30: =SUM(H6:H29) -> 4
B31: Вывод (сумма > 12 — strong, < −12 — weak) | C31: =IF(C30>12,"strong",IF(C30<-12,"weak","mixed")) -> mixed | D31: =IF(D30>12,"strong",IF(D30<-12,"weak","mixed")) -> mixed | E31: =IF(E30>12,"strong",IF(E30<-12,"weak","mixed")) -> mixed | F31: =IF(F30>12,"strong",IF(F30<-12,"weak","mixed")) -> mixed | G31: =IF(G30>12,"strong",IF(G30<-12,"weak","mixed")) -> mixed | H31: =IF(H30>12,"strong",IF(H30<-12,"weak","mixed")) -> mixed
B33: Совпали во всех 5 прогонах (из 24) | C33: =COUNTIF(I6:I29,"да") -> 24
B34: Вывод одинаков во всех 5 прогонах | C34: =IF(COUNTIF(C31:G31,C31)=5,"да","нет") -> да
B35: Сумма по прогонам: минимум | C35: =MIN(C30:G30) -> 4
B36: Сумма по прогонам: максимум | C36: =MAX(C30:G30) -> 4

Sheet 2025_q4
A1: 4 кв. и 12 мес. 2025: оценки пяти прогонов
A2: Исходный файл: ifrs_results_q4_1pbxnuiy_2025.pdf
A3: Прогоны отличаются только порядком показателей в запросе. Итог — медиана пяти оценок (совпадает с самым частым значением). «нет» в колонке I — хрупкая клетка, её нужно проверить человеку.
A5: Блок | B5: Показатель | C5: Прогон 1 | D5: Прогон 2 | E5: Прогон 3 | F5: Прогон 4 | G5: Прогон 5 | H5: Итог (медиана) | I5: Совпали во всех 5 | J5: Кто ставит
A6: Прибыльность | B6: Чистая прибыль | C6: 1 | D6: 1 | E6: 1 | F6: 1 | G6: 1 | H6: =MEDIAN(C6:G6) -> 1 | I6: =IF(MAX(C6:G6)=MIN(C6:G6),"да","нет") -> да | J6: код
A7: Прибыльность | B7: Прибыль на акцию (EPS) | C7: 1 | D7: 1 | E7: 1 | F7: 1 | G7: 1 | H7: =MEDIAN(C7:G7) -> 1 | I7: =IF(MAX(C7:G7)=MIN(C7:G7),"да","нет") -> да | J7: код
A8: Прибыльность | B8: Рентабельность капитала (ROE) | C8: -1 | D8: -1 | E8: -1 | F8: -1 | G8: -1 | H8: =MEDIAN(C8:G8) -> -1 | I8: =IF(MAX(C8:G8)=MIN(C8:G8),"да","нет") -> да | J8: код
A9: Прибыльность | B9: Прогноз менеджмента | C9: 1 | D9: 1 | E9: 1 | F9: 1 | G9: 1 | H9: =MEDIAN(C9:G9) -> 1 | I9: =IF(MAX(C9:G9)=MIN(C9:G9),"да","нет") -> да | J9: модель
A10: Доходы | B10: Чистые процентные доходы | C10: 2 | D10: 2 | E10: 2 | F10: 2 | G10: 2 | H10: =MEDIAN(C10:G10) -> 2 | I10: =IF(MAX(C10:G10)=MIN(C10:G10),"да","нет") -> да | J10: код
A11: Доходы | B11: Чистые комиссионные доходы | C11: -1 | D11: -1 | E11: -1 | F11: -1 | G11: -1 | H11: =MEDIAN(C11:G11) -> -1 | I11: =IF(MAX(C11:G11)=MIN(C11:G11),"да","нет") -> да | J11: код
A12: Доходы | B12: Чистая процентная маржа (NIM) | C12: 1 | D12: 1 | E12: 1 | F12: 1 | G12: 1 | H12: =MEDIAN(C12:G12) -> 1 | I12: =IF(MAX(C12:G12)=MIN(C12:G12),"да","нет") -> да | J12: код
A13: Эффективность | B13: Операционные расходы | C13: -1 | D13: -1 | E13: -1 | F13: -1 | G13: -1 | H13: =MEDIAN(C13:G13) -> -1 | I13: =IF(MAX(C13:G13)=MIN(C13:G13),"да","нет") -> да | J13: код
A14: Эффективность | B14: Отношение расходов к доходам (CIR) | C14: -2 | D14: -2 | E14: -2 | F14: -2 | G14: -2 | H14: =MEDIAN(C14:G14) -> -2 | I14: =IF(MAX(C14:G14)=MIN(C14:G14),"да","нет") -> да | J14: код
A15: Риск | B15: Стоимость риска (CoR) | C15: 1 | D15: 1 | E15: 1 | F15: 1 | G15: 1 | H15: =MEDIAN(C15:G15) -> 1 | I15: =IF(MAX(C15:G15)=MIN(C15:G15),"да","нет") -> да | J15: код
A16: Риск | B16: Расходы на резервы | C16: 2 | D16: 2 | E16: 2 | F16: 2 | G16: 2 | H16: =MEDIAN(C16:G16) -> 2 | I16: =IF(MAX(C16:G16)=MIN(C16:G16),"да","нет") -> да | J16: код
A17: Риск | B17: Качество портфеля | C17: -1 | D17: -1 | E17: -1 | F17: -1 | G17: -1 | H17: =MEDIAN(C17:G17) -> -1 | I17: =IF(MAX(C17:G17)=MIN(C17:G17),"да","нет") -> да | J17: модель
... A29: Среда | B29: Тональность руководителя | C29: 2 | D29: 1 | E29: 0 | F29: 1 | G29: -1 | H29: =MEDIAN(C29:G29) -> 1 | I29: =IF(MAX(C29:G29)=MIN(C29:G29),"да","нет") -> нет | J29: модель
B30: Сумма 24 оценок | C30: =SUM(C6:C29) -> 13 | D30: =SUM(D6:D29) -> 12 | E30: =SUM(E6:E29) -> 11 | F30: =SUM(F6:F29) -> 13 | G30: =SUM(G6:G29) -> 11 | H30: =SUM(H6:H29) -> 13
B31: Вывод (сумма > 12 — strong, < −12 — weak) | C31: =IF(C30>12,"strong",IF(C30<-12,"weak","mixed")) -> strong | D31: =IF(D30>12,"strong",IF(D30<-12,"weak","mixed")) -> mixed | E31: =IF(E30>12,"strong",IF(E30<-12,"weak","mixed")) -> mixed | F31: =IF(F30>12,"strong",IF(F30<-12,"weak","mixed")) -> strong | G31: =IF(G30>12,"strong",IF(G30<-12,"weak","mixed")) -> mixed | H31: =IF(H30>12,"strong",IF(H30<-12,"weak","mixed")) -> strong
B33: Совпали во всех 5 прогонах (из 24) | C33: =COUNTIF(I6:I29,"да") -> 21
B34: Вывод одинаков во всех 5 прогонах | C34: =IF(COUNTIF(C31:G31,C31)=5,"да","нет") -> нет
B35: Сумма по прогонам: минимум | C35: =MIN(C30:G30) -> 11
B36: Сумма по прогонам: максимум | C36: =MAX(C30:G30) -> 13

Sheet 2026_q1
A1: 1 кв. 2026: оценки пяти прогонов
A2: Исходный файл: results_q1_a3s5t86k_2026.pdf
A3: Прогоны отличаются только порядком показателей в запросе. Итог — медиана пяти оценок (совпадает с самым частым значением). «нет» в колонке I — хрупкая клетка, её нужно проверить человеку.
A5: Блок | B5: Показатель | C5: Прогон 1 | D5: Прогон 2 | E5: Прогон 3 | F5: Прогон 4 | G5: Прогон 5 | H5: Итог (медиана) | I5: Совпали во всех 5 | J5: Кто ставит
A6: Прибыльность | B6: Чистая прибыль | C6: 2 | D6: 2 | E6: 2 | F6: 2 | G6: 2 | H6: =MEDIAN(C6:G6) -> 2 | I6: =IF(MAX(C6:G6)=MIN(C6:G6),"да","нет") -> да | J6: код
A7: Прибыльность | B7: Прибыль на акцию (EPS) | C7: 2 | D7: 2 | E7: 2 | F7: 2 | G7: 2 | H7: =MEDIAN(C7:G7) -> 2 | I7: =IF(MAX(C7:G7)=MIN(C7:G7),"да","нет") -> да | J7: код
A8: Прибыльность | B8: Рентабельность капитала (ROE) | C8: 0 | D8: 0 | E8: 0 | F8: 0 | G8: 0 | H8: =MEDIAN(C8:G8) -> 0 | I8: =IF(MAX(C8:G8)=MIN(C8:G8),"да","нет") -> да | J8: код
A9: Прибыльность | B9: Прогноз менеджмента | C9: 0 | D9: 0 | E9: 0 | F9: 0 | G9: 0 | H9: =MEDIAN(C9:G9) -> 0 | I9: =IF(MAX(C9:G9)=MIN(C9:G9),"да","нет") -> да | J9: модель
A10: Доходы | B10: Чистые процентные доходы | C10: 2 | D10: 2 | E10: 2 | F10: 2 | G10: 2 | H10: =MEDIAN(C10:G10) -> 2 | I10: =IF(MAX(C10:G10)=MIN(C10:G10),"да","нет") -> да | J10: код
A11: Доходы | B11: Чистые комиссионные доходы | C11: 0 | D11: 0 | E11: 0 | F11: 0 | G11: 0 | H11: =MEDIAN(C11:G11) -> 0 | I11: =IF(MAX(C11:G11)=MIN(C11:G11),"да","нет") -> да | J11: код
A12: Доходы | B12: Чистая процентная маржа (NIM) | C12: 0 | D12: 0 | E12: 0 | F12: 0 | G12: 0 | H12: =MEDIAN(C12:G12) -> 0 | I12: =IF(MAX(C12:G12)=MIN(C12:G12),"да","нет") -> да | J12: код
A13: Эффективность | B13: Операционные расходы | C13: 1 | D13: 1 | E13: 1 | F13: 1 | G13: 1 | H13: =MEDIAN(C13:G13) -> 1 | I13: =IF(MAX(C13:G13)=MIN(C13:G13),"да","нет") -> да | J13: код
A14: Эффективность | B14: Отношение расходов к доходам (CIR) | C14: 0 | D14: 0 | E14: 0 | F14: 0 | G14: 0 | H14: =MEDIAN(C14:G14) -> 0 | I14: =IF(MAX(C14:G14)=MIN(C14:G14),"да","нет") -> да | J14: код
A15: Риск | B15: Стоимость риска (CoR) | C15: 0 | D15: 0 | E15: 0 | F15: 0 | G15: 0 | H15: =MEDIAN(C15:G15) -> 0 | I15: =IF(MAX(C15:G15)=MIN(C15:G15),"да","нет") -> да | J15: код
A16: Риск | B16: Расходы на резервы | C16: -2 | D16: -2 | E16: -2 | F16: -2 | G16: -2 | H16: =MEDIAN(C16:G16) -> -2 | I16: =IF(MAX(C16:G16)=MIN(C16:G16),"да","нет") -> да | J16: код
A17: Риск | B17: Качество портфеля | C17: 0 | D17: 1 | E17: 1 | F17: 1 | G17: 1 | H17: =MEDIAN(C17:G17) -> 1 | I17: =IF(MAX(C17:G17)=MIN(C17:G17),"да","нет") -> нет | J17: модель
... A29: Среда | B29: Тональность руководителя | C29: 1 | D29: 1 | E29: 1 | F29: 1 | G29: 1 | H29: =MEDIAN(C29:G29) -> 1 | I29: =IF(MAX(C29:G29)=MIN(C29:G29),"да","нет") -> да | J29: модель
